Workbook

Sheet 📈 Dashboard
A38: Raw Data hidden below v
A39: Raw Data per tab | C39: Don't touch | E39: Don't touch | G39: Don't touch | I39: Don't touch | K39: Don't touch | M39: Don't touch
A40: Staging Modo.us
C41: Desktop | D41: Android | E41: iOS | G41: Test Cases | H41: =#REF! -> #REF! | I41: Categories | J41: =COUNTA(B41:F41) -> 3 | K41: To Check | L41: =H41*J41 -> #REF!
B42: Pass | C42: =#REF! -> #REF! | D42: =#REF! -> #REF! | E42: =#REF! -> #REF!
B43: Acceptable | C43: =#REF! -> #REF! | D43: =#REF! -> #REF! | E43: =#REF! -> #REF!
B44: Fail | C44: =#REF! -> #REF! | D44: =#REF! -> #REF! | E44: =#REF! -> #REF!
B45: N/A | C45: =#REF! -> #REF! | D45: =#REF! -> #REF! | E45: =#REF! -> #REF!
B46: Remaining | C46: =#REF! -> #REF! | D46: =#REF! -> #REF! | E46: =#REF! -> #REF!
B47: Overall progress | C47: =#REF! -> #REF! | D47: =#REF! -> #REF! | E47: =#REF! -> #REF!
A49: Givaways/Tournaments
C50: Desktop | D50: Android | E50: iOS | G50: Test Cases | H50: =Games!C7 -> 43 | I50: Categories | J50: =COUNTA(B50:F50) -> 3 | K50: To Check | L50: =H50*J50 -> 129
B51: Pass | C51: =Games!F2 -> 0.41860465 | D51: =Games!L2 -> 0 | E51: =Games!H2 -> 0.46511628
B52: Acceptable | C52: =Games!F3 -> 0.11627907 | D52: =Games!L3 -> 0.069767442 | E52: =Games!H3 -> 0.069767442
B53: Fail | C53: =Games!F4 -> 0.1627907 | D53: =Games!L4 -> 0.1627907 | E53: =Games!H4 -> 0.1627907
B54: N/A | C54: =Games!F5 -> 0 | D54: =Games!L5 -> 0 | E54: =Games!H5 -> 0
B55: Remaining | C55: =Games!F6 -> 0.023255814 | D55: =Games!L6 -> 0.023255814 | E55: =Games!H6 -> 0.046511628
B56: Overall progress | C56: =Games!F7 -> 0.97674419 | D56: =Games!L7 -> 0.97674419 | E56: =Games!H7 -> 0.95348837
A58: Back office
C59: Desktop | G59: Test Cases | H59: =#REF! -> #REF! | I59: Categories | J59: =COUNTA(B59:F59) -> 1 | K59: To Check | L59: =H59*J59 -> #REF!
B60: Pass | C60: =#REF! -> #REF!
B61: Acceptable | C61: =#REF! -> #REF!
B62: Fail | C62: =#REF! -> #REF!
B63: N/A | C63: =#REF! -> #REF!
B64: Remaining | C64: =#REF! -> #REF!
B65: Overall progress | C65: =#REF! -> #REF!
A67: Payments
C68: Fiserv | D68: Checkout | G68: Test Cases | H68: =#REF! -> #REF! | I68: Categories | J68: =COUNTA(B68:F68) -> 2 | K68: To Check | L68: =H68*J68 -> #REF!
B69: Pass | C69: =#REF! -> #REF! | D69: =#REF! -> #REF!
B70: Acceptable | C70: =#REF! -> #REF! | D70: =#REF! -> #REF!
B71: Fail | C71: =#REF! -> #REF! | D71: =#REF! -> #REF!
B72: N/A | C72: =#REF! -> #REF! | D72: =#REF! -> #REF!
B73: Remaining | C73: =#REF! -> #REF! | D73: =#REF! -> #REF!
B74: Overall progress | C74: =#REF! -> #REF! | D74: =#REF! -> #REF!
A76: Redemptions
C77: Fiserv | D77: Checkout | E77: Bank account | F77: Prizeout | G77: Test Cases | H77: #REF! | I77: Categories | J77: =COUNTA(B77:F77) -> 4 | K77: To Check | L77: =H77*J77 -> #REF!
B78: Pass | C78: #REF! | D78: #REF! | E78: #REF! | F78: #REF!
B79: Acceptable | C79: #REF! | D79: #REF! | E79: #REF! | F79: #REF!
B80: Fail | C80: #REF! | D80: #REF! | E80: #REF! | F80: #REF!
B81: N/A | C81: #REF! | D81: #REF! | E81: #REF! | F81: #REF!
...

Sheet TP Index
A1: Staging Modo.us | B1: Results | C1: Games | D1: Results 2 | E1: Back Office (BO) | F1: Results 3 | G1: Cohorts | H1: Results 4 | I1: Payments | J1: Results 5 | K1: Redemptions | L1: Results 6
A2: Geoblock page | C2: Giveaways | E2: Players | G2: Tournament cohorts | I2: No 3DS - Debit card | K2: Bank account first redemption - Manual approval (Sent)
A3: Landing page | C3: Tournaments | E3: Transactions | G3: Banner cohorts | I3: No 3DS - Credit card | K3: Bank account redemption - Automatic scheduled
A4: Logged out lobby | C4: Hot Games Now | E4: Banners | G4: Game Group cohorts | I4: 3DS - Debit card - Transation accepted | K4: Debit card first redemption - Manual approval (Sent)
A5: New account - Onboarding | C5: Modo Originals | E5: Giveaways | I5: 3DS - Debit card - Transation rejected | K5: Debit card redemption - Automatic scheduled - VIP level below Gold II
A6: Logged in lobby | E6: Challenges | F6: N/A | I6: 3DS - Credit card - Transation accepted | K6: Debit card redemption - Automatic approval (Sent) - VIP level >= Gold II
A7: My Profile | E7: Rewards | I7: 3DS - Credit card - Transation rejected | K7: Prizeout redemption - Automatic scheduled
A8: Lobby tab | E8: Packages | I8: CVV check | K8: Redemption cancelled
A9: My Profile | E9: Promotions | I9: AVS check (Billing address check) | K9: Redemption rejected
A10: Games tab | E10: Payments | I10: Automatic Risk level changes | K10: Redemption reversed
A11: Modo Boxes tab | B11: N/A | E11: Chargebacks | I11: Additional Test
A12: Promotion tab | E12: Velocity Controls | F12: N/A | I12: Additional Payment Methods
A13: Refer a Friend section + Store | E13: Redemptions
A14: Daily Bonus Streaks section | E14: Installment Plans
A15: VIP Ranks section | E15: Games
A16: Redeem tab | E16: Game Categories
A17: FAQ tab | E17: Feature Flags
A18: Live Chat tab | E18: Roles
A19: Notifications button | E19: Free Play Campaigns | F19: N/A
A20: Account statuses and restricted actions | E20: External Systems | F20: N/A
A21: Responsible gaming tab - Purchase limits | E21: Logout
A22: Streak Repair
A23: Wheel Spin
A24: GPS geoblock

Sheet Smoke suite status
C1: Total tests: | D1: =COUNTIF(E:E, "Pending") + COUNTIF(E:E, "Done") + COUNTIF(E:E, "In Progress") + COUNTIF(E:E, "TBD") -> 170 | E1: NON-DUPLICATE COUNT | F1: {=COUNTA(UNIQUE(F4:F1019))} -> 1
B3: Team | C3: Test description | D3: Priority | E3: Status | F3: QA Wolf test name | G3: Duplicate Coverage
B4: Core | C4: GC only Store | D4: 1 | E4: Done | F4: GC only Store
B5: Core | C5: GC only First time shopper | D5: 2 | E5: Done | F5: GC only First time shopper
B6: Core | C6: Check GC only Welcome Bonus | D6: 3 | E6: Done | F6: Check GC only Welcome Bonus
B7: Core | C7: GC only Daily login bonus | D7: 4 | E7: Done | F7: GC only Daily login bonus GC only Wheel Spin
B8: Core | C8: GC only VIP promotions | D8: 5 | E8: Done | F8: GC only VIP promotions
B9: Core | C9: Remove SC bonus from referrals | D9: 6 | E9: Done | F9: Remove SC bonus from referrals
B10: Marketing | C10: GC only rewards (state restrictions) | D10: 7 | E10: Done | F10: GC only rewards (state restrictions)
B11: Payments | C11: GC only disable redemptions | D11: 8 | E11: Done | F11: GC only disable redemptions
B12: Games | C12: GC only disable SC toggle in Lobby | D12: 9 | E12: Done | F12: GC only disable SC toggle in Lobby
B13: Games | C13: GC only hide SC toggle in game preview modal | D13: 10 | E13: Done | F13: GC only hide SC toggle in game preview modal
B14: Marketing | C14: Previous year review & announcement modal | D14: 11 | E14: In Progress | F14: Previous year review & announcement modal
B15: Marketing | C15: Modo ranks info page | D15: 12 | E15: In Progress | F15: Modo ranks info page
... B20: Marketing | C20: Modo rank up | D20: 17 | E20: In Progress | F20: Modo rank up
B21: Marketing | C21: Invite/Uninvite to Exclusive Ranks - Black Diamond I | D21: 18 | E21: TBD
B22: Marketing | C22: Invite/Uninvite to Exclusive Ranks - Black Diamond II | D22: 19 | E22: TBD
B23: Marketing | C23: Invite/Uninvite to Exclusive Ranks - Black Diamond III | D23: 20 | E23: TBD
B24: Marketing | C24: Existing Black Diamond users | D24: 21 | E24: TBD
B25: Marketing | C25: Giveaway/Tournament cohort | D25: 22 | E25: TBD
B26: Marketing | C26: Gold Coins store | D26: 23 | E26: TBD
B27: Marketing | C27: Modo Stars Store | D27: 24 | E27: TBD
B28: Marketing | C28: Redeem Stars | D28: 25 | E28: TBD
B29: Marketing | C29: Earning Modo stars through GC play | D29: 26 | E29: TBD
B30: Core | C30: Block AMOE code generation page | D30: 27 | E30: TBD | F30: N/A
B31: Core | C31: Hide low on SC flow - Onboarding | D31: 28 | E31: TBD | F31: N/A
B32: Core | C32: Hide low on SC flow - Lobby | D32: 29 | E32: TBD | F32: N/A
B33: Games | C33: Check Modo Original games: Blackjack (Implement given feedback) | D33: 30 | E33: TBD | F33: N/A
B34: Games | C34: Check Modo Original games: Roulette (Implement given feedback) | D34: 31 | E34: TBD | F34: N/A
B35: Games | C35: Check Modo Original games: Mines | E35: TBD | F35: N/A
B36: Games | C36: Check Modo Original games: Dice | E36: TBD | F36: N/A
B37: Games | C37: Check Modo Original games: Wheel | E37: TBD | F37: N/A
B38: Games | C38: Check Modo Original games: Limbo | E38: TBD | F38: N/A
B39: Core | C39: Login with Facebook - New auth flow | E39: TBD | F39: Login with Facebook
B40: Core | C40: Login with Apple - New auth flow | E40: TBD | F40: Login with Apple
B41: Core | C41: Login with Email - New auth flow | E41: TBD | F41: N/A
B42: Payments | C42: Request 1st bank redemption | E42: TBD | F42: N/A
B43: Payments | C43: Request 1st debit redemption (Fiserv 1960 card) | E43: TBD | F43: N/A
B44: Payments | C44: Request Gift card | E44: TBD | F44: N/A
B45: Marketing | C45: Play Tournament game | E45: TBD | F45: Play Tournament Games
...

Sheet Core Stats
A1: QA Wolf Workflow Name | B1: Area | C1: QA Wolf Status | D1: ARB Status | E1: Release blocker? | R1: Date | S1: QA Wolf tests | T1: Duration
A2: =#REF! -> #REF! | B2: Modo | C2: =#REF! -> #REF! | D2: =#REF! -> #REF! | E2: =#REF! -> #REF! | R2: 45911 | S2: 0 | T2: 50 minutes (Active work time) Around 3 hours total with other responsabilities
A3: =#REF! -> #REF! | B3: Modo | C3: =#REF! -> #REF! | D3: =#REF! -> #REF! | E3: =#REF! -> #REF! | R3: - | S3: 5 | T3: -
A4: =#REF! -> #REF! | B4: Modo | C4: =#REF! -> #REF! | D4: =#REF! -> #REF! | E4: =#REF! -> #REF! | R4: - | S4: 10 | T4: -
A5: =#REF! -> #REF! | B5: Modo | C5: =#REF! -> #REF! | D5: =#REF! -> #REF! | E5: =#REF! -> #REF! | R5: - | S5: 15 | T5: -
A6: =#REF! -> #REF! | B6: Modo | C6: =#REF! -> #REF! | D6: =#REF! -> #REF! | E6: =#REF! -> #REF! | R6: - | S6: 20 | T6: -
A7: =#REF! -> #REF! | B7: Modo | C7: =#REF! -> #REF! | D7: =#REF! -> #REF! | E7: =#REF! -> #REF! | R7: - | S7: 26 (All) | T7: -
A8: =#REF! -> #REF! | B8: Modo | C8: =#REF! -> #REF! | D8: =#REF! -> #REF! | E8: =#REF! -> #REF!
A9: =#REF! -> #REF! | B9: Modo | C9: =#REF! -> #REF! | D9: =#REF! -> #REF! | E9: =#REF! -> #REF!
A10: =#REF! -> #REF! | B10: Modo | C10: =#REF! -> #REF! | D10: =#REF! -> #REF! | E10: =#REF! -> #REF!
A11: =#REF! -> #REF! | B11: Modo | C11: =#REF! -> #REF! | D11: =#REF! -> #REF! | E11: =#REF! -> #REF!
A12: =#REF! -> #REF! | B12: Modo | C12: =#REF! -> #REF! | D12: =#REF! -> #REF! | E12: =#REF! -> #REF!
A13: =#REF! -> #REF! | B13: Modo | C13: =#REF! -> #REF! | D13: =#REF! -> #REF! | E13: =#REF! -> #REF!
A14: =#REF! -> #REF! | B14: Modo | C14: =#REF! -> #REF! | D14: =#REF! -> #REF! | E14: =#REF! -> #REF!
A15: =#REF! -> #REF! | B15: Modo | C15: =#REF! -> #REF! | D15: =#REF! -> #REF! | E15: =#REF! -> #REF!
A16: =#REF! -> #REF! | B16: Modo | C16: =#REF! -> #REF! | D16: =#REF! -> #REF! | E16: =#REF! -> #REF!
A17: =#REF! -> #REF! | B17: Modo | C17: =#REF! -> #REF! | D17: =#REF! -> #REF! | E17: =#REF! -> #REF! | G17: Release blocker? | H17: #REF! | M17: Release blocker? | N17: #REF!
A18: =#REF! -> #REF! | B18: Modo | C18: =#REF! -> #REF! | D18: =#REF! -> #REF! | E18: =#REF! -> #REF!
A19: =#REF! -> #REF! | B19: Modo | C19: =#REF! -> #REF! | D19: =#REF! -> #REF! | E19: =#REF! -> #REF! | G19: QA Wolf Status | H19: COUNTA of QA Wolf Status | M19: QA Wolf Status | N19: COUNTA of QA Wolf Status
A20: =#REF! -> #REF! | B20: Modo | C20: =#REF! -> #REF! | D20: =#REF! -> #REF! | E20: =#REF! -> #REF! | G20: #REF! | H20: 106 | M20: #REF! | N20: 106
A21: =#REF! -> #REF! | B21: Modo | C21: =#REF! -> #REF! | D21: =#REF! -> #REF! | E21: =#REF! -> #REF! | G21: Grand Total | H21: 106 | M21: Grand Total | N21: 106
A22: =#REF! -> #REF! | B22: Modo | C22: =#REF! -> #REF! | D22: =#REF! -> #REF! | E22: =#REF! -> #REF!
A23: =#REF! -> #REF! | B23: Modo | C23: =#REF! -> #REF! | D23: =#REF! -> #REF! | E23: =#REF! -> #REF!
A24: =#REF! -> #REF! | B24: Modo | C24: =#REF! -> #REF! | D24: =#REF! -> #REF! | E24: =#REF! -> #REF!
A25: =#REF! -> #REF! | B25: Modo | C25: =#REF! -> #REF! | D25: =#REF! -> #REF! | E25: =#REF! -> #REF!
A26: =#REF! -> #REF! | B26: Modo | C26: =#REF! -> #REF! | D26: =#REF! -> #REF! | E26: =#REF! -> #REF!
A27: =#REF! -> #REF! | B27: Modo | C27: =#REF! -> #REF! | D27: =#REF! -> #REF! | E27: =#REF! -> #REF!
A28: =#REF! -> #REF! | B28: Modo | C28: =#REF! -> #REF! | D28: =#REF! -> #REF! | E28: =#REF! -> #REF!
A29: =#REF! -> #REF! | B29: Modo | C29: =#REF! -> #REF! | D29: =#REF! -> #REF! | E29: =#REF! -> #REF!
A30: =#REF! -> #REF! | B30: Modo | C30: =#REF! -> #REF! | D30: =#REF! -> #REF! | E30: =#REF! -> #REF!
A31: =#REF! -> #REF! | B31: Modo | C31: =#REF! -> #REF! | D31: =#REF! -> #REF! | E31: =#REF! -> #REF!
A32: =#REF! -> #REF! | B32: Modo | C32: =#REF! -> #REF! | D32: =#REF! -> #REF! | E32: =#REF! -> #REF!
A33: =#REF! -> #REF! | B33: Modo | C33: =#REF! -> #REF! | D33: =#REF! -> #REF! | E33: =#REF! -> #REF!
... A107: =#REF! -> #REF! | B107: Modo | C107: =#REF! -> #REF! | D107: =#REF! -> #REF! | E107: =#REF! -> #REF!

Sheet Games
B1: V2 | C1: Cell color coding | F1: Desktop | G1: iOS (APP) | H1: iOS (PWA) | I1: iOS (Browser) | J1: Android (APP) | K1: Android (PWA) | L1: Android (Browser) | M1: At least 1 checked | O1: Testing notes: Difference between Rewards, Click & Claim, Giveaways and Tournaments Rewards: These are given to users for a variety of reasons, these are collected by users from the Click & Claim reward modal that appears once they have been awarded GC/SC for any of the following reasons: - VIP Rank ups - VIP level related weekly/montly Click & Claims (These are usually handled by the Marketing team, but just for context, depending on the users GC/SC plays and their VIP level, they would receive back some GC/SC based on a %) - Marketing promotions - Giveaway/Tournament prizes Click & Claim: As mentioned above, these are presented to the user through a modal where they can claim their GC/SC rewards (they would receive an email as well in some instances, again this is something mostly handled by Marketing, as QA we just need to Ensure the modal can be triggered, that there are no errors on the modal and that the GC/SC is credited as intended) Giveaways: This is an in-game Modo feature that gives players the oportunity to win extra GC/SC rewards by playing the games that are part of an active Giveaway Tournament: Like Giveaways, Tournaments are an in-game Modo feature that gives players the chance to win extra GC/SC rewards but this time by placing at the top of the leaderboard by winning in the games that are part of an active Tournament.
C2: Improvement: The feature/section being tested works but could be improved | E2: Pass | F2: =COUNTIF($F$10:F42,$E$2)/$C$7 -> 0.41860465 | G2: =COUNTIF(G$10:$H42,$E$2)/$C$7 -> 0.93023256 | H2: =COUNTIF(H$10:$H42,$E$2)/$C$7 -> 0.46511628 | I2: =COUNTIF(H$10:$I42,$E$2)/$C$7 -> 0.93023256 | J2: =COUNTIF($L$10:L14,$E$2)/$C$7 -> 0 | K2: =COUNTIF($L$10:L14,$E$2)/$C$7 -> 0 | L2: =COUNTIF($L$10:L14,$E$2)/$C$7 -> 0
C3: N/A: The test case only applies to a column(s) or the feature is not ready to test yet | E3: Improvement | F3: =COUNTIF($F$10:F42,$E$3)/$C$7 -> 0.11627907 | G3: =COUNTIF(G$10:$H42,$E$3)/$C$7 -> 0.13953488 | H3: =COUNTIF(H$10:$H42,$E$3)/$C$7 -> 0.069767442 | I3: =COUNTIF(H$10:$I42,$E$3)/$C$7 -> 0.13953488 | J3: =COUNTIF($L$10:L42,$E$3)/$C$7 -> 0.069767442 | K3: =COUNTIF($L$10:L42,$E$3)/$C$7 -> 0.069767442 | L3: =COUNTIF($L$10:L42,$E$3)/$C$7 -> 0.069767442
C4: Fail: The feature/section is broken/blocked. Stops flow or high visibility issue | E4: Fail | F4: =COUNTIF($F$10:F42,$E$4)/$C$7 -> 0.1627907 | G4: =COUNTIF(G$10:$H42,$E$4)/$C$7 -> 0.3255814 | H4: =COUNTIF(H$10:$H42,$E$4)/$C$7 -> 0.1627907 | I4: =COUNTIF(H$10:$I42,$E$4)/$C$7 -> 0.3255814 | J4: =COUNTIF($L$10:L42,$E$4)/$C$7 -> 0.1627907 | K4: =COUNTIF($L$10:L42,$E$4)/$C$7 -> 0.1627907 | L4: =COUNTIF($L$10:L42,$E$4)/$C$7 -> 0.1627907
E5: N/A | F5: =COUNTIF($F$10:F42,$E$5)/$C$7 -> 0 | G5: =COUNTIF(G$10:$H42,$E$5)/$C$7 -> 0 | H5: =COUNTIF(H$10:$H42,$E$5)/$C$7 -> 0 | I5: =COUNTIF(H$10:$I42,$E$5)/$C$7 -> 0 | J5: =COUNTIF($L$10:L42,$E$5)/$C$7 -> 0 | K5: =COUNTIF($L$10:L42,$E$5)/$C$7 -> 0 | L5: =COUNTIF($L$10:L42,$E$5)/$C$7 -> 0
E6: Remaining | F6: =COUNTIFS($F$10:F42, "", $F$10:F42, "<>N/A", $F$10:F42, "<>.") / $C$7 -> 0.023255814 | G6: =COUNTIFS(G$10:$H42, "", G$10:$H42, "<>N/A", G$10:$H42, "<>.") / $C$7 -> 0.069767442 | H6: =COUNTIFS(H$10:$H42, "", H$10:$H42, "<>N/A", H$10:$H42, "<>.") / $C$7 -> 0.046511628 | I6: =COUNTIFS(H$10:$I42, "", H$10:$I42, "<>N/A", H$10:$I42, "<>.") / $C$7 -> 0.069767442 | J6: =COUNTIFS($L$10:L42, "", $L$10:L42, "<>N/A", $L$10:L42, "<>.") / $C$7 -> 0.023255814 | K6: =COUNTIFS($L$10:L42, "", $L$10:L42, "<>N/A", $L$10:L42, "<>.") / $C$7 -> 0.023255814 | L6: =COUNTIFS($L$10:L42, "", $L$10:L42, "<>N/A", $L$10:L42, "<>.") / $C$7 -> 0.023255814
B7: Total TCs: | C7: =COUNTIF(A:A,"TC") -> 43 | E7: Overall progress | F7: =100% - F6 -> 0.97674419 | G7: =100% - G6 -> 0.93023256 | H7: =100% - H6 -> 0.95348837 | I7: =100% - I6 -> 0.93023256 | J7: =100% - J6 -> 0.97674419 | K7: =100% - K6 -> 0.97674419 | L7: =100% - L6 -> 0.97674419
A9: Title | B9: Area | C9: Test case | D9: Steps | E9: Expected result | F9: Result | G9: Result | H9: Result | I9: Result | J9: Result | K9: Result | L9: Result | M9: Result | N9: Bug # | O9: Comments | T9: QA Wolf Workflow Name | U9: QA Wolf Status | V9: ARB Status | W9: ARB Comments | X9: QA Wolf Comments
A10: Title | B10: 1PG / Modo Originals | F10: . | G10: . | H10: . | I10: . | J10: . | K10: . | L10: . | M10: .
A11: TC | B11: Check Modo Originals games | C11: Shared Components | D11: • Check the common elements that are shared across all games *ONLY fill these cells once all games have been checked | E11: • Settings button options: ◦ Ensure the following Menu options are present and work as intended: - Game Info - includes all game rules, and game rules are accurate, and RTP is correct - Fairness - can copy Active Client Seed and Server Seed Hash, and can update Client Seed ◦ Ensure the following Settings options are present and work as intended: - Instant Play toggles on/off and correctly enables/disables instant play - Mute/Unmute toggles and correctly enables/disables sounds - Cheats toggles on/off and correctly enables/disables Cheat: Forced Outcome (IMPORTANT: Cheats should NOT be present in Prod) + Cheat: Forced Outcome functions as intended • Ensure game is SL-compliant. • Ensure plays and wins are awarded to the account as intended. - Play history is shown in-game (if applicable) • Ensure rollbacks are functioning as intended and logged to the account. • Ensure game is performant and lag-free.
C12: Plinko | D12: • Search for Modo Originals in the search bar • Launch Plinko and play & win using GC and SC | E12: • Ensure the following UI elements are present and work as intended: - Number of rows: Can pick and play from 8 through 16 - Risk Profile: Can pick and play Low|Medium|High - Play amount: 10 should appear as default for GC and 1 for SC but can type in any amount between minimum up to actual balance on the account. Other options here should be 1/2, 2x and Max. - Total balance of the account should appear next to Play amount and update in semi-realtime - Information icon next to Play amount: Ensure all 5 pages are displayed as intended and have no issues - Play button: Ensure the button works as intended and that the text changes from "Play" to "Insufficient Coins" whenever the play amount is higher than the actual balance (Should only happen when playing the last coins available on the account as typing in a higher amount than current balance would default to balance number). - Settings: Ensure volume and skip visual effects work as intended (special effects refer mostly to the animation triggered when clicking on the Play button) • Ensure multipliers are awarded correctly (no need to check all of them, but check a couple using a variation of rows + risk profiles) | F12: Fail | G12: Fail | H12: Fail | I12: Fail | J12: Fail | K12: Fail | L12: Fail | N12: LOY-153 LOY-205 | O12: VL STAGING iOS 12/10/25: Minor issue: a small misalignment of “Number of Rows” in browsers. TLB STAGING & PROD Android 12/11/25 &12/22/25: Button sounds are not working correctly (Repeated issue). VL STAGING iOS 12/22/25: Rollback plays are not reflected in the Back Office (BO) and are also missing from the Coin History section. - Also happening on Desktop & Android TLB 12/22/25 | T12: Plinko - Insufficient Funds Plinko - Risk Profile Plinko - Skip Visual Effects Plinko - Verify Game Renders and Play Game Plinko - Verify Number of Rows Plinko - Volume | U12: Draft | V12: Needs Automation
A13: TC | C13: Blackjack | D13: • Search for Modo Originals in the search bar • Launch Blackjack and play & win using GC and SC | E13: • Ensure the following UI elements are present and work as intended: - Play amounts: SC can be set from 0.1 to 10K, no half decimals (e.g. 0.12), GC from 1000 to 1000000 - Play amount divider and multiplier works, and are disabled when reaching the minimum and maximum amount, respectively - Play button works - Hit works (except on Split Aces) - Stand works - Split works (when splitting Aces, no more plays are possible) - Double works - Insurance prompts to Accept & Decline work (0.5x side play win if accepted) - Even Coins prompts to Accept & Decline work (2x win if accepted aka 1:1 win) - Blackjack win works (2.5x aka 1.5:1) | F13: Fail | G13: Fail | H13: Fail | I13: Fail | J13: Fail | K13: Fail | L13: Fail | O13: VL STAGING iOS 12/22/25: Rollback plays are not reflected in the Back Office (BO) and are also missing from the Coin History section. - Also happening on Desktop & Android TLB 12/22/25 | T13: Blackjack - Decline Even Coins Blackjack - Decline Insurance Blackjack - Even Coins Win Blackjack - Insurance Lose Blackjack - Insurance Win Blackjack - Lose Blackjack - Push Blackjack - Win | U13: Draft | V13: Needs Automation
A14: TC | C14: Roulette | D14: • Search for Modo Originals in the search bar • Launch Roulette and play & win using GC and SC | E14: • Ensure the menu's UI elements are present and work as intended: - Chip Value & value # - Chip selection & scroll - Play Amount (label) & value # - Play Amount (current #), 1/2 & 2x buttons - Play button • Ensure the Roulette UI's elements are present and work as intended: - 35:1 (Numbers 0-36. Only test one or a couple, please randomize them) - 2:1 (Dozens, 1 to 12, 13 to 24, 25 to 36, and Columns) 1:1 (Red / Black, Odd / Even, Low 1 to 18 / High 19 to 36) - Undo and Clear | F14: Fail | G14: Fail | H14: Fail | I14: Fail | J14: Fail | K14: Fail | L14: Fail | M14: Improvement | N14: LOY-126 LOY-207 | O14: VL STAGING iOS 12/22/25: Rollback plays are not reflected in the Back Office (BO) and are also missing from the Coin History section. - Also happening on Desktop & Android TLB 12/22/25 TLB STAGING 12/22/25: - The UI is zoomed in too close and cuts off the undo/clear buttons. (Desktop) - Clicking on the Instant Play button while the ball is spinning on the table will make the table stop spinning while while the ball is still spinning in play. (Android) | T14: Roulette - Draw Roulette - Loss Roulette - Placeholder Roulette - Undo and Clear Buttons Roulette - Wins - 1 to 12, 13 to 24, or 25 to 36 Roulette - Wins - Red/Black or Even/Odd Roulette - Wins - Single Number | U14: Draft | V14: Needs Automation
A15: TC | C15: Wheel | D15: • Search for Modo Originals in the search bar • Launch Wheel and play & win using GC and SC | E15: • Ensure the following UI elements are present and work as intended: - Play Amount input (100 GC min, 0.1 SC min, 10M GC max, 10K SC max) - 1/2 and 2x buttons (No decimals should occur unless it's the entire balance. Test w/ low decimal balances so that when you reach your max, it'll set your entire balance as the play amount) - Risk profile: Can pick and play Low|Medium|High - Segments profile: Can pick and play 10|20|30|40|50 - Play button works as intended • Ensure history elements correctly match amount and color | F15: Fail | G15: Fail | H15: Fail | I15: Fail | J15: Fail | K15: Fail | L15: Fail | O15: VL STAGING iOS 12/22/25: Rollback plays are not reflected in the Back Office (BO) and are also missing from the Coin History section. - Also happening on Desktop & Android TLB 12/22/25 | U15: Blocked | V15: Needs Automation
A16: TC | C16: Limbo | D16: • Search for Modo Originals in the search bar • Launch Limbo and play & win using GC and SC | E16: • Ensure the following UI elements are present and work as intended: - Play Amount input (100 GC min, 1 SC min, GC max, 5000 SC max) - 1/2 and 2x buttons (No decimals should occur unless it's the entire balance. Test w/ low decimal balances so that when you reach your max, it'll set your entire balance as the play amount) - Multiplier and Win Chance • Ensure history elements correctly match amount and color | F16: Fail | G16: Fail | H16: Fail | I16: Fail | J16: Fail | K16: Fail | L16: Fail | N16: LOY-190 | O16: VL STAGING iOS 12/22/25: Rollback plays could not be tested because they require an Admin toggle. The game is restricted on Staging. - Also happening on Desktop & Android TLB 12/22/25 | U16: Blocked | V16: Needs Automation
A17: TC | C17: Dice | D17: • Search for Modo Originals in the search bar • Launch Dice and play & win using GC and SC | E17: • Ensure the following UI elements are present and work as intended: - Play Amount input (100 GC min, 0.1 SC min, 10M GC max, 10K SC max) - 1/2 and 2x buttons (No decimals should occur unless it's the entire balance. Test w/ low decimal balances so that when you reach your max, it'll set your entire balance as the play amount) - Under / Over buttons and its roll prediction input (up & down arrows, minimum prediction is 4, max is 99, and can input decimals) - Multiplier and Win Chance adjust according to prediction - Multiplier and its arrows (min is 1.01, max is 97, and can input decimals that will be adjusted to its nearest valid decimal value) - Win Chance and its arrows (min is 1%, max is 96%, and can enter decimals) - Play button works as intended | F17: Fail | G17: Fail | H17: Fail | I17: Fail | J17: Fail | K17: Fail | L17: Fail | O17: VL STAGING iOS 12/22/25: Rollback plays could not be tested because they require an Admin toggle. The game is restricted on Staging. - Also happening on Desktop & Android as well TLB 12/22/25 | U17: Blocked | V17: Needs Automation
A18: TC | C18: Mines | D18: • Search for Modo Originals in the search bar • Launch Mines and play & win using GC and SC | E18: • Ensure the following UI elements are present and work as intended: - Play amounts: SC can be set from 1 to 5K, GC from 1k to 10M - Play amount divider and multiplier works, and are disabled when reaching the minimum and maximum amount, respectively - Number of Mines slider adjusts from 1|24 to 24|1 (default is 12|13) - Play button - Random Pick works (once round starts, clicking on it picks randomly) - Net Gain updates with correct coin amount - Next: #.##x updates with correct multiplier amount - Each tile works as intended - Collect (once round starts, Play button becomes "Collect") - Once Collect is clicked, multiplier with total win (net gain + original play amount) is shown | F18: Fail | G18: Fail | H18: Fail | I18: Fail | J18: Fail | K18: Fail | L18: Fail | O18: VL STAGING iOS 12/22/25: Rollback plays are not reflected in the Back Office (BO) and are also missing from the Coin History section. - Also happening on Desktop & Android 12/22/25 TLB STAGING Dekstop & Android 12/22/25: 'Payouts' SL issue in the game rules | U18: Blocked | V18: Needs Automation
A19: Title | B19: Modo - Games | F19: . | G19: . | I19: . | J19: . | K19: . | L19: . | M19: .
A20: TC | B20: Logged out lobby | C20: Check Search bar | D20: • Select the Search bar and type in part of a game's name, the game's full name, and the game provider's name | E20: • Ensure searching for part of the game's name, the full game's name or the Game provider's name would show the intended results as expected (Please note the search bar does not allow typos) | F20: Improvement | G20: Improvement | H20: Improvement | I20: Improvement | J20: Improvement | K20: Improvement | L20: Improvement | N20: GAME-1569 GAME-1743 | O20: STAGING: No results are shown when fully typing out the provider and the game title in the search results -TLB 11/17/25 Desktop (Chrome), Android (PWA + Browser), All iOS ALL envs & platforms: Searhc param does not auto-clear on lobby return | T20: Search by Partial and Full Game Name and Game Provider's name | U20: Draft | V20: Needs Automation
A21: TC | C21: Check Games tab | D21: • Select Games tab from side bar | E21: • Ensure the Games tab redirects to Games page • Ensure only the search bar, login button, register button, game categories and page footer is visible | F21: Pass | G21: Pass | H21: Pass | I21: Pass | J21: Pass | K21: Pass | L21: Pass | T21: Check Games Tab | U21: Draft | V21: Needs Automation
C22: Check Latest Winners section | D22: • Select any game from the Latest Winners section • Swipe right/left to navigate through the games in the Latest Winners section | E22: • Ensure selecting any game from the Latest Winners section redirects to Login page • Ensure you can swipe right/left or that arrows work as intended • Ensure the Latest Winners tiles show the following: - Game thumbnail - Game name - Player name - GC or SC win - State | F22: Pass | G22: Pass | H22: Pass | I22: Pass | J22: Pass | K22: Pass | L22: Pass
A23: TC | C23: Check Popular Now section | D23: • Select any game from the Popular Now section • Swipe right/left to navigate through the games in the Popular now section • Select the arrows in Popular Now section • For mobile, use swipe right/left as there are no arrows to scroll through the games | E23: • Ensure selecting any game from the Popular now section redirects to login page • Ensure arrows work as intended • For mobile, ensure you can swipe games left/right • Ensure the Popular now tiles show the following: - Game thumbnail - Game name - Game provider - Number of players - Play button | F23: Pass | G23: Pass | H23: Pass | I23: Pass | J23: Pass | K23: Pass | L23: Pass | U23: Not Found | V23: Needs Automation | W23: Only logged in lobby draft found
A24: TC | C24: Check Game categories | D24: • Select any Game category besides Lobby • Swipe right/left to navigate through the Game categories • For mobile, the game category bar is replaced by the filter button next to search bar | E24: • Ensure selecting any Game category only shows the games from the selected category + the page footer below. All other Game categories should not be visible. • Ensure you can swipe right/left or that arrows work as intended • Ensure "View all" button works as intended • For mobile, ensure the filter button works as intended | F24: Pass | G24: Pass | H24: Pass | I24: Pass | J24: Pass | K24: Pass | L24: Pass | N24: GAME-1741 | O24: TLB STAGING: The Game categories bar does not fully scroll to the end and makes the final game category to be less visible to the user - Desktop (Chrome) 12/29/25 | U24: Not Found | V24: Needs Automation
A25: TC | C25: Check Top 10 games category | D25: • Select Lobby Game category • Select the View all 10 games button • Select arrows in Top 10 games category • Swipe right/left to navigate through the Top 10 games section • Select any game from the Top 10 games section | E25: • Ensure selecting the View all 10 games button shows the Top 10 games category (same behavior as selecting the Top 10 games category itself • Ensure you can swipe right/left or that arrows work as intended • Ensure the Top 10 games tiles show the following: - Game thumbnail - Game name - Game provider - Tag(s) (Desktop only) - Volatility (Desktop only) • Ensure selecting any game from the Top 10 section redirects to Login page | F25: Pass | G25: Pass | H25: Pass | I25: Pass | J25: Pass | K25: Pass | L25: Pass | T25: Logged out Lobby: Check Top 10 games category | U25: Draft | V25: Needs Automation
A26: TC | C26: Check Our Providers section | D26: • Select the arrows in Our Providers section • Swipe right/left to navigate through Providers | E26: • Ensure you can swipe right/left or that arrows work as intended • Ensure the Provider tiles show the following: - Provider logo - Number of games • Ensure selecting a provider filters for said provider/shows said provider's category | F26: Pass | G26: Pass | H26: Pass | I26: Pass | J26: Pass | K26: Pass | L26: Pass | T26: Logged out Lobby: Check Our Providers section | U26: Draft | V26: Needs Automation
A27: TC | C27: Check Hot Now section - Top 3 Winning games | D27: • Select any game from the Hot Now section | E27: • Ensure selecting any game from the Popular now section redirects to Login page • Ensure the Hot Now section shows the following: - Game thumbnail - Game name - Game provider - Player name - State ("Winner" text below it) - GC/SC win amount ("Biggest win" text below it) | F27: Pass | G27: Pass | H27: Pass | I27: Pass | J27: Pass | K27: Pass | L27: Pass | T27: Check Hot Now section - Top 3 Winning games | U27: Draft | V27: Needs Automation
A28: TC | C28: Check Game categories in lobby | D28: • Select the Lobby Game category • Navigate up/down in the lobby to check the same Game categories found in the Game category bar (Note: Game categories with 7 games or more will show the "View all" button and arrows to navigate through the games. Same behavior found in the Top 10 games category | E28: • Ensure the same Game categories found in the category bar can be found as section in the lobby below • Ensure the "View all" button, arrows and swipe work as intended (when applicable) | F28: Pass | G28: Pass | H28: Pass | I28: Pass | J28: Pass | K28: Pass | L28: Pass | N28: GAME-1747 | O28: TLB STAGING: The user is directed to the footer instead of the header of the page after clicking 'View all' on any of the game categories in the lobby. - Android (Chrome), Android (PWA) | U28: Not Found | V28: Needs Automation
A29: TC | C29: Check All games category | D29: • Select any game in the All games category • Select the Load More button | E29: • Ensure selecting any game from the All games category redirects to Login page • Ensure the Load More button shows more games as intended | F29: Improvement | G29: Pass | H29: Pass | I29: Pass | J29: Pass | K29: Pass | L29: Pass | N29: GAME-1663 | O29: STAGING & PROD: All games no longer filling up rows for larger desktops - TLB 12/9/25 Desktop (Chrome) | T29: Logged out Lobby: Load More Games and Select a Game | U29: Not Found | V29: Needs Automation
A30: TC | B30: Logged in lobby | C30: Check Search bar and play game with SC and GC coins | D30: • Select the Search bar and type in part of a game's name, the game's full name, and the game provider's name • Launch the game in GC and play some spins • Go back to lobby, change the coins to SC from the tabs in the upper right corner, launch the game in SC and play some spins | E30: • Ensure searching for part of the game's name, the full game's name or the Game provider's name would show the intended results as expected (Please note the search bar does not allow typos) • Ensure the information in the game modal is correct (including the Play with Sweepstakes Coins/Gold Coins depending on the tab selected in the lobby) • Ensure the game is able to be opened in both coin types NOTE: Will change with new search function | F30: Improvement | G30: Improvement | H30: Improvement | I30: Improvement | J30: Improvement | K30: Improvement | L30: Improvement | N30: GAME-1569 GAME-1743 | O30: STAGING: No results are being shown when fully typing out the provider and the game title in the search results -TLB & VL 11/17/25 Desktop (Chrome), Android (PWA + Browser), All iOS ALL envs & platforms: Searhc param does not auto-clear on lobby return | T30: Play a GC or SC spin on any game and then return to the Lobby | U30: Done | V30: Approved
A31: TC | C31: Check Popular Now section | D31: • Select any game from the Popular now section • Swipe right/left to navigate through the games in the Popular now section • Select the arrows in Popular Now section | E31: • Ensure you can swipe right/left or that arrows work as intended • Ensure the Popular now tiles show the following: - Game thumbnail - Game name - Game provider - Number of players - Play button • Ensure selecting any game from the Popular now section shows the game modal as intended • Ensure you can open the game from said modal | F31: Pass | G31: Pass | H31: Pass | I31: Pass | J31: Pass | K31: Pass | L31: Pass | T31: Logged in Lobby: Check Popular now section | U31: Draft | V31: Needs Automation
A32: TC | C32: Check Game categories | D32: • Select any Game category besides Lobby • Swipe right/left to navigate through the Game categories Note: On Mobile categories appear as "Filters" where you can filter out specific categories | E32: • Ensure selecting any Game category only shows the games from the selected category + the page footer below. All other Game categories shows not be visible. • Ensure you can swipe right/left or that arrows work as intended • Ensure "View all" button works as intended • For mobile, ensure the filter button works as intended NOTE: Will change with new search function | F32: Pass | G32: Pass | H32: Pass | I32: Pass | J32: Pass | K32: Pass | L32: Pass | N32: GAME-1741 | O32: TLB PROD: Providers are included in the games category bar while the 'Our Providers' section is enabled. - 12/19/25 Desktop (Chrome) TLB STAGING: The Game categories bar does not fully scroll to the end and makes the final game category to be less visible to the user - 12/29/25 Desktop (Chrome) | U32: Not Found | V32: Needs Automation
C33: Check Continue Playing section | D33: • Launch any game on GC or SC and then return to the Lobby | E33: • Ensure the first game in Continue Playing is the game you just launched | F33: Pass | G33: Pass | H33: Pass | I33: Pass | J33: Pass | K33: Pass | L33: Pass
A34: TC | C34: Check Recommended For You section | D34: • This section works as a paid spot for game developers to position their games higher, which means there is no relation to recently played games, etc. • Swipe right right/left to navigate through the games • Select the arrows in Recommended For You section • Select "View all" button • Select any game | E34: • Ensure you can swipe right/left or that arrows work as intended • Ensure the "View all" button shows only the recommended games as intended • Ensure any game from this category can be launched as intended | F34: Pass | G34: Pass | H34: Pass | I34: Pass | J34: Pass | K34: Pass | L34: Pass | U34: Not Found | V34: Needs Automation
A35: TC | C35: Check Top 10 games category | D35: • Select Lobby Game category • Select the View all 10 games button • Select arrows in Top 10 games category • Swipe right/left to navigate through the Top 10 games section • Select any game from the Top 10 games section | E35: • Ensure selecting the View all 10 games button shows the Top 10 games category (same behavior as selecting the Top 10 games category itself • Ensure you can swipe right/left or that arrows work as intended • Ensure the Top 10 games tiles show the following: - Game thumbnail - Game name - Game provider - Tag(s) • Ensure selecting any game from the Popular now section shows the game modal as intended | F35: Pass | G35: Pass | H35: Pass | I35: Pass | J35: Pass | K35: Pass | L35: Pass | U35: Not Found | V35: Needs Automation | W35: Only logged out lobby draft found
C36: Check Latest Winners section | D36: • Select any game from the Latest Winners section • Swipe right/left to navigate through the games in the Latest WInners section • Select arrows in Latest Winners section | E36: • Ensure selecting any game from the Latest Winners section shows the game modal as intended • Ensure you can swipe right/left or that arrows work as intended • Ensure the Latest Winners tiles show the following: - Game thumbnail - Game name - Game provider - Player name - GC or SC win - State | F36: Pass | G36: Pass | H36: Pass | I36: Pass | J36: Pass | K36: Pass | L36: Pass
C37: Check Our Providers section | D37: • Select the arrows in Our Providers section • Swipe right/left to navigate through Providers | E37: • Ensure you can swipe right/left or that arrows work as intended • Ensure the Provider tiles show the following: - Provider logo - Number of games • Ensure selecting a provider filters for said provider/shows said provider's category | F37: Pass | G37: Pass | H37: Pass | I37: Pass | J37: Pass | K37: Pass | L37: Pass | V37: Needs Automation
A38: TC | C38: Check Hot Now section - Top 3 Winning games | D38: • Select any game from the Hot Now section | E38: • Ensure selecting any game from the Popular now section shows the game modal as intended • Ensure you can swipe right/left or that arrows work as intended • Ensure the Hot Now section shows the following: - Game thumbnail - Player name - State ("Winner" text below it) - GC/SC win amount ("Biggest win" text below it) • Ensure the selected game opens | F38: Pass | G38: Pass | H38: Pass | I38: Pass | J38: Pass | K38: Pass | L38: Pass | U38: Not Found | V38: Needs Automation | W38: Only logged out lobby draft found
A39: TC | C39: Check Game categories in lobby | D39: • Select the Lobby Game category (on mobile, it's the default unfiltered) • Navigate up/down in the lobby to check the same Game categories found in the Game category bar (Note: Game categories with 7 games or more will show the "View all" button and arrows to navigate thorugh the games. Same behavior found in the Top 10 games category described in row #29) | E39: • Ensure the same Game categories found in the category bar can be found as section in the lobby below • Ensure you can swipe right/left or that arrows work as intended • Ensure the "View all" button, arrows and swipe work as intended (when applicable) | F39: Pass | G39: Pass | H39: Pass | I39: Pass | J39: Pass | K39: Pass | L39: Pass | O39: TLB STAGING: "View all" button directs the user to the footer instead of the header on the page. - Android (APP version 1.0.0.10.1) | U39: Not Found | V39: Needs Automation
A40: TC | C40: Check All games category | D40: • Select any game in the All games category • Select the Load More button | E40: • Ensure selecting any game from the All games category shows the game modal as intended • Ensure the Load More button shows more games as intended | F40: Improvement | G40: Pass | H40: Pass | I40: Pass | J40: Pass | K40: Pass | L40: Pass | N40: GAME-1663 | O40: STAGING & PROD: All games no longer filling up rows for larger desktops - TLB 12/11/25 Desktop (Chrome) | U40: Not Found | V40: Needs Automation | W40: Only logged out lobby draft found
A41: TC | C41: Check Games tab | D41: • Select Games tab • For mobile, select the Games tab from the side bar and from the bottom navigation bar | E41: • Ensure the Games tab redirects to Games page • Ensure the banners, Popular Now, and Latest Winners are NOT shown (everything else should be equal to the Lobby) • For mobile, ensure the Games tab from the side bar and from the bottom navigation bar redirect to Games page | F41: Pass | G41: Pass | H41: Pass | I41: Pass | J41: Pass | K41: Pass | L41: Pass | U41: Not Found | V41: Request Assertions | W41: Only logged out lobby draft found Request assertions: • For mobile, Ensure the Games tab from the side bar and from the bottom navigation bar redirect to Games page
...

Sheet Games BO
B1: V2 | C1: Cell color coding | F1: Desktop | G1: Android | H1: iOS | I1: At least 1 checked | K1: Testing notes: Back office is the admin area where we can search/edit accounts, add/remove games, promotions, banners, etc. Different teams have different accesses and uses for BO, for example, CS agents would only have read access to user accounts. QA have all read/edit accesses in the Staging environment but only read access in the Production environment. These tests should be focused on the functionality and possible improvements to the workflows as this is exclusively used for admins and of course not client facing, which means UI issues are low priority. There are 2 side bar menus in BO, the general one and the Player one which only appears if you select a User ID and access their specific information. The actions are similar but in the general side bar menu you see information from all users, while in the Player side bar menu you will see information related to the specific user you are looking at. (Note: BO can only be accessed through Desktop computer)
C2: Improvement - The feature/section being tested works but could be improved | E2: Pass | F2: =COUNTIF($F$10:F15,$E$2)/$C$7 -> 1 | G2: =COUNTIF($G$10:G15,$E$2)/$C$7 -> 0 | H2: =COUNTIF($H$10:H15,$E$2)/$C$7 -> 0
C3: N/A - The test case only applies to a column(s) or the feature is not ready to test yet | E3: Improvement | F3: =COUNTIF($F$10:F15,$E$3)/$C$7 -> 0 | G3: =COUNTIF($G$10:G15,$E$3)/$C$7 -> 0 | H3: =COUNTIF($H$10:H15,$E$3)/$C$7 -> 0
C4: Fail - The feature/section being tested is broken/blocked. Stops flow or high visibilty issue | E4: Fail | F4: =COUNTIF($F$10:F15,$E$4)/$C$7 -> 0 | G4: =COUNTIF($G$10:G15,$E$4)/$C$7 -> 0 | H4: =COUNTIF($H$10:H15,$E$4)/$C$7 -> 0
E5: N/A | F5: =COUNTIF($F$10:F15,$E$5)/$C$7 -> 0 | G5: =COUNTIF($G$10:G15,$E$5)/$C$7 -> 0 | H5: =COUNTIF($H$10:H15,$E$5)/$C$7 -> 0
E6: Remaining | F6: =COUNTIFS($F$11:F15, "", $F$11:F15, "<>N/A", $F$11:F15, "<>.") /$C$7 -> 0 | G6: =COUNTIFS($G$10:G15, "", $G$10:G15, "<>N/A", $G$10:G15, "<>.") /$C$7 + G5 -> 1.6666667 | H6: =COUNTIFS($H$10:H15, "", $H$10:H15, "<>N/A", $H$10:H15, "<>.") /$C$7 + H5 -> 1.6666667
B7: Total TCs: | C7: =COUNTIF(A:A,"TC") -> 3 | E7: Overall progress | F7: =100% - F6 -> 1 | G7: =100% - G6 -> -0.66666667 | H7: =100% - H6 -> -0.66666667
A9: Title | B9: Area | C9: Test case | D9: Steps | E9: Expected result | F9: Result | G9: Result | H9: Result | I9: Result | J9: Bug # | K9: Comments | P9: QA Wolf Workflow Name | Q9: QA Wolf Status | R9: ARB Status | S9: Release blocker? | T9: ARB Comments | U9: QA Wolf Comments
A10: Title | B10: Games | F10: . | G10: . | H10: . | I10: .
A11: TC | B11: Games | C11: Check General - Games tab | D11: • Select the general Games tab • Search any game by name and by Provider • Select any Game ID (Note: The Bulk update and Edit options are handled by the QA members in charged of uploading new games to Staging/Prod. No need to check these options for now) | E11: • Ensure all elements, buttons, layout are displayed properly, and that the text is correct • Ensure the Search option works as intended • Ensure selecting any Game ID redirects you to the Game info page (No need to edit info here) | F11: Pass | J11: GAME-1338 | K11: VL 11/12/25: Provider and Name search not working.
A12: Title | B12: Game Groups | F12: .
A13: TC | B13: Game Groups | C13: Check General - Game Groups tab (Previously known as Game Categories) | D13: (Note: Game Groups are located just below the search bar (Top Games, Live Gaming Casino, etc.) • Select the general Game Groups tab • Select New and fill in the fields as follows: - Name: You can enter any test name although we recommend using something that can help you recognize it (e.g. Test # date and your initials like "Test 1 12/25 FS") - Slug: This is the text displayed in the URL, could use something like Test-1-1225-FS, following the name format - Tag: Could be "Test" - Icon URL: This is the category icon that appears next to the category name within the button. Could use this test image: https://modous-public-bucket.s3.amazonaws.com/icons/Modo.us.svg https://modous-public-bucket.s3.us-east-1.amazonaws.com/icons/Modo-Logo-vegas3.png - Icon V2 URL: Can use https://modous-public-bucket.s3.us-east-1.amazonaws.com/category-icons/jackpot-play/cyan.png - Badges: Select any Badge you would like to use. These appear in the game's thumbnail - Start/End Date: Can be left blank - Cohorts will be tested in the Cohorts tab from this spreadsheet, can ignore for now • Select Create • Drag and drop the category created from the bottom of the list to the top, this will make it appear as the first category • Select the Game Group ID, select Edit, Type in any Game name you would like to include in the category, uncheck the Is Restricted box and select Update | E13: • Ensure all elements, buttons, layout are displayed properly, and that the text is correct • Ensure the Game Group was created properly. - Check on any test account to see if the Game Group is available in the Modo Lobby just below the "Popular now" section and below the latest winners section, and ensure that selecting the category will show the game you entered while updating the category. • Ensure the category can be deleted once these previous tests have been completed. The category should not appear anymore once deleted. | F13: Pass | J13: GAME-1549
B14: Game Group cohorts | F14: .
A15: TC | B15: Game group cohorts | C15: Check Game Group cohorts | D15: • The same steps and information from Tournament cohorts apply here. Create a Game Group using the steps from the Game Groups section in the BO tab, and add at least 2 cohorts • Find a test user that does not meet any of the cohorts selected • Add the cohort conditions one by one and confirm if the Banner only appears once these conditions have been met | E15: • Ensure the Game Group can be created while using cohorts • Ensure the cohorts added have been saved successfully once the Game Group has been created • Ensure the test user cannot see the Game Group while their account does not meet the cohort conditions • Ensure the user can see the Game Group once their account meets the cohort conditions (or test with another non-admin account that meets the cohort conditions) | F15: Pass

Sheet Games_GCSC
F1: Desktop | G1: Android | H1: iOS | I1: At least 1 checked | K1: Testing notes: There are different types of games (Slots, Instant win, Dare to win, Table games, Live games) as well as different game aggregators (Publishers) and game providers (game dev studios). The purpose of these tests is to Ensure the games run properly in the Staging environment as a pre check before deploying into the Production environment. (Although there are some exceptions where the games are tested directly in the Production environment while being hidden from real users)
E2: Pass | F2: =COUNTIF($F$11:F64,$E$2)/$C$7 -> 0 | G2: =COUNTIF($G$11:AA64,$E$2)/$C$7 -> 0 | H2: =COUNTIF($H$11:H64,$E$2)/$C$7 -> 0
E3: Acceptable | F3: =COUNTIF($F$11:F64,$E$3)/$C$7 -> 0 | G3: =COUNTIF($G$11:G64,$E$3)/$C$7 -> 0 | H3: =COUNTIF($H$11:H64,$E$3)/$C$7 -> 0
E4: Fail | F4: =COUNTIF($F$11:F64,$E$4)/$C$7 -> 0 | G4: =COUNTIF($G$11:G64,$E$4)/$C$7 -> 0 | H4: =COUNTIF($H$11:H64,$E$4)/$C$7 -> 0
E5: N/A | F5: =COUNTIF($F$11:F64,$E$5)/$C$7 -> 0 | G5: =COUNTIF($G$11:G64,$E$5)/$C$7 -> 0 | H5: =COUNTIF($H$11:H64,$E$5)/$C$7 -> 0
E6: Remaining | F6: =COUNTIFS($F$11:F64, "", $F$11:F64, "<>N/A", $F$11:F64, "<>.") /$C$7 + F5 -> 1 | G6: =COUNTIFS($G$11:G64, "", $G$11:G64, "<>N/A", $G$11:G64, "<>.") /$C$7 + G5 -> 1 | H6: =COUNTIFS($H$11:H64, "", $H$11:H64, "<>N/A", $H$11:H64, "<>.") /$C$7 + H5 -> 1
B7: Total TCs: | C7: =COUNTIF(A:A,"TC") -> 47 | E7: Overall progress | F7: =100% - F6 -> 0 | G7: =100% - G6 -> 0 | H7: =100% - H6 -> 0
A9: Title | B9: Aggregator | C9: Game provider | D9: Test case | E9: Expected result | F9: Result | G9: Result | H9: Result | I9: Result | J9: Bug # | K9: QA Comments (Please add your initials to the comment) | L9: Additional Info
A10: Title | F10: . | G10: . | H10: . | I10: .
A11: TC | B11: N/A | C11: N/A | D11: General checks for all games (These checks only need to be tested once on any game) | E11: • Ensure the thumbnail (aka thumbnailLogo) of the game you are checking is displayed clearly and that the name on the thumbnail matches the name displayed when you select a game (Including symbols like ™, etc.) • Ensure selecting any game opens the game preview modal • Ensure all elements, buttons, layout from the game preview modal are displayed properly, including the following: •In-game screenshot (aka popupLogo) is displayed clearly • The name of the game is correct and matches the name on thumbnail • The Gold coins and Sweepstakes coins buttons work as intended • The top prize is displayed • Min/Max is displayed • Volatility is displayed • The Play with Gold coins/Sweepstakes coins button work as intended • For GC, Ensure you can't spin anymore if you spend all GC coins and try a new spin • For GC, Ensure exiting the game after spending all GC coins would show a modal which gives 1000 GC coins for the user to keep playing • For SC, Ensure you can't spin anymore if you spend all SC coins and try a new spin • For SC, Ensure exiting the game would trigger a package discount offer to the player • Ensure the game rules, menus, in-game buttons use the appropriate social casino language
A12: Title | F12: . | G12: . | H12: . | I12: .
A13: TC | B13: Booming | C13: Booming | D13: • Play 1 spin on SC | E13: • Ensure the game launches properly and SC spins work as intended
A14: TC | D14: • Play 1 spin on GC | E14: • Ensure the game launches properly and GC spins work as intended
A15: Title | F15: . | G15: . | H15: . | I15: .
A16: TC | B16: Casimba | C16: 3Oaks | D16: • Play 1 spin on SC | E16: • Ensure the game launches properly and SC spins work as intended
A17: TC | D17: • Play 1 spin on GC | E17: • Ensure the game launches properly and GC spins work as intended
A18: TC | C18: BGaming | D18: • Play 1 spin on SC | E18: • Ensure the game launches properly and SC spins work as intended
A19: TC | D19: • Play 1 spin on GC | E19: • Ensure the game launches properly and GC spins work as intended
A20: TC | C20: Evoplay | D20: • Play 1 spin on SC | E20: • Ensure the game launches properly and SC spins work as intended
A21: TC | D21: • Play 1 spin on GC | E21: • Ensure the game launches properly and GC spins work as intended
A22: TC | D22: • Play 1 spin on SC on a table game (E.x. Blackjack) | E22: • Ensure the game launches properly and SC spins work as intended
A23: TC | D23: • Play 1 spin on GC on a table game (E.x. Blackjack) | E23: • Ensure the game launches properly and GC spins work as intended
A24: TC | C24: Habanero | D24: • Play 1 spin on SC | E24: • Ensure the game launches properly and SC spins work as intended
A25: TC | D25: • Play 1 spin on GC | E25: • Ensure the game launches properly and GC spins work as intended
A26: TC | C26: Netgaming | D26: • Play 1 spin on SC | E26: • Ensure the game launches properly and SC spins work as intended
A27: TC | D27: • Play 1 spin on GC | E27: • Ensure the game launches properly and GC spins work as intended
A28: TC | C28: Playson | D28: • Play 1 spin on SC | E28: • Ensure the game launches properly and SC spins work as intended
A29: TC | D29: • Play 1 spin on GC | E29: • Ensure the game launches properly and GC spins work as intended
A30: TC | C30: RubyPlay | D30: • Play 1 spin on SC | E30: • Ensure the game launches properly and SC spins work as intended
A31: TC | D31: • Play 1 spin on GC | E31: • Ensure the game launches properly and GC spins work as intended
A32: Title | F32: . | G32: . | H32: . | I32: .
A33: TC | B33: Hacksaw | C33: Hacksaw | D33: • Play 1 spin on SC | E33: • Ensure the game launches properly and SC spins work as intended
A34: TC | D34: • Play 1 spin on GC | E34: • Ensure the game launches properly and GC spins work as intended
A35: Title | F35: . | G35: . | H35: . | I35: .
A36: TC | B36: Fizzy Bubbly | C36: Avatar UX | D36: • Play 1 spin on SC | E36: • Ensure the game launches properly and SC spins work as intended
A37: TC | D37: • Play 1 spin on GC | E37: • Ensure the game launches properly and GC spins work as intended
A38: TC | C38: Novomatic | D38: • Play 1 spin on SC | E38: • Ensure the game launches properly and SC spins work as intended
A39: TC | D39: • Play 1 spin on GC | E39: • Ensure the game launches properly and GC spins work as intended
A40: TC | C40: Rogue | D40: • Play 1 spin on SC | E40: • Ensure the game launches properly and SC spins work as intended
A41: TC | D41: • Play 1 spin on GC | E41: • Ensure the game launches properly and GC spins work as intended
...

Sheet Issue tracker
A1: Row # | B1: Tab name | C1: Comments | D1: Issue Type | E1: Priority | F1: Status | G1: Next steps/comments
A2: 11 | B2: Staging Modo.us | C2: =#REF! -> #REF!
A3: 12 | B3: Staging Modo.us | C3: =#REF! -> #REF!
A4: 13 | B4: Staging Modo.us | C4: =#REF! -> #REF!
A5: 14 | B5: Staging Modo.us | C5: =#REF! -> #REF!
A6: 15 | B6: Staging Modo.us | C6: =#REF! -> #REF!
A7: 16 | B7: Staging Modo.us | C7: =#REF! -> #REF!
A8: 17 | B8: Staging Modo.us | C8: =#REF! -> #REF!
A9: 18 | B9: Staging Modo.us | C9: =#REF! -> #REF!
A10: 19 | B10: Staging Modo.us | C10: =#REF! -> #REF!
A11: 20 | B11: Staging Modo.us | C11: =#REF! -> #REF!
A12: 21 | B12: Staging Modo.us
A13: 22 | B13: Staging Modo.us
A14: 23 | B14: Staging Modo.us
A15: 24 | B15: Staging Modo.us
A16: 25 | B16: Staging Modo.us
A17: 26 | B17: Staging Modo.us
A18: 27 | B18: Staging Modo.us
A19: 28 | B19: Staging Modo.us | C19: =#REF! -> #REF!
A20: 29 | B20: Staging Modo.us | C20: =#REF! -> #REF!
A21: 30 | B21: Staging Modo.us | C21: =#REF! -> #REF!
A22: 31 | B22: Staging Modo.us | C22: =#REF! -> #REF!
A23: 32 | B23: Staging Modo.us | C23: =#REF! -> #REF!
A24: 33 | B24: Staging Modo.us | C24: =#REF! -> #REF!
A25: 34 | B25: Staging Modo.us | C25: =#REF! -> #REF!
A26: 36 | B26: Staging Modo.us | C26: =#REF! -> #REF!
A27: 38 | B27: Staging Modo.us
A28: 39 | B28: Staging Modo.us
A29: 40 | B29: Staging Modo.us
A30: 41 | B30: Staging Modo.us
A31: 42 | B31: Staging Modo.us
A32: 43 | B32: Staging Modo.us | C32: =#REF! -> #REF!
A33: 48 | B33: Staging Modo.us | C33: =#REF! -> #REF!
A34: 49 | B34: Staging Modo.us | C34: =#REF! -> #REF!
A35: 50 | B35: Staging Modo.us | C35: =#REF! -> #REF!
A36: 51 | B36: Staging Modo.us | C36: =#REF! -> #REF!
A37: 52 | B37: Staging Modo.us | C37: =#REF! -> #REF!
A38: 53 | B38: Staging Modo.us | C38: =#REF! -> #REF!
A39: 56 | B39: Staging Modo.us | C39: =#REF! -> #REF!
A40: 58 | B40: Staging Modo.us | C40: =#REF! -> #REF!
...

Sheet Test CardsBank
A1: Test cards | B1: Pay processor documentation | C1: Test Routing number
A2: Visa | B2: Checkout | C2: DECORAH BANK & TRUST COMPANY
A3: Debit/3DS 4099000000001960 | B3: Test cards - https://www.checkout.com/docs/developer-resources/testing/test-cards | C3: 073921695
A4: Credit 4147463011110083 | B4: CVV check - https://www.checkout.com/docs/developer-resources/testing/simulate-card-verification-outcomes
B5: AVS check - https://www.checkout.com/docs/developer-resources/testing/avs-check-testing
A6: Mastercard | B6: Fiserv
A7: Credit/3DS 5544330000000235 | B7: Test cards - https://docs.fiserv.com/docs/payments/ZG9jOjgwMjA1NjY-test-card-numbers
A10: Amex
A11: Credit 345678901234564
A13: Discover
A14: Credit 6011111111111117
